Workbook
Name Slicer_Priority: #N/A
Name Slicer_Tier: #N/A

Sheet Tickets
A1: TicketID | B1: DateLogged | C1: Priority | D1: Category | E1: Tier | F1: Status | G1: SLA_Target_Hours | H1: ResolvedDateTime | I1: ResolutionHours | J1: SLA_Status | K1: Owner | L1: MonthLogged
A2: TCK-0001 | B2: 45744.686 | C2: P3 | D2: Access | E2: L2 | F2: Closed | G2: 24 | H2: 45747.033 | I2: =IF(H2="","",(H2-B2)*24) -> 56.308045 | J2: =IF(H2="","Open",IF(I2<=G2,"Met","Breached")) -> Breached | K2: K. Padilla | L2: =DATE(YEAR(B2),MONTH(B2),1) -> 45717
A3: TCK-0002 | B3: 45748.357 | C3: P3 | D3: Access | E3: L1 | F3: Closed | G3: 24 | H3: 45749.754 | I3: =IF(H3="","",(H3-B3)*24) -> 33.551181 | J3: =IF(H3="","Open",IF(I3<=G3,"Met","Breached")) -> Breached | K3: K. Padilla | L3: =DATE(YEAR(B3),MONTH(B3),1) -> 45748
A4: TCK-0003 | B4: 45972.352 | C4: P3 | D4: Bug | E4: L1 | F4: Open | G4: 24 | I4: =IF(H4="","",(H4-B4)*24) | J4: =IF(H4="","Open",IF(I4<=G4,"Met","Breached")) -> Open | K4: J. Ncube | L4: =DATE(YEAR(B4),MONTH(B4),1) -> 45962
A5: TCK-0004 | B5: 45954.512 | C5: P3 | D5: Data | E5: L1 | F5: Resolved | G5: 24 | H5: 45955.731 | I5: =IF(H5="","",(H5-B5)*24) -> 29.262088 | J5: =IF(H5="","Open",IF(I5<=G5,"Met","Breached")) -> Breached | K5: K. Padilla | L5: =DATE(YEAR(B5),MONTH(B5),1) -> 45931
A6: TCK-0005 | B6: 45706.478 | C6: P3 | D6: Access | E6: L2 | F6: In Progress | G6: 24 | I6: =IF(H6="","",(H6-B6)*24) | J6: =IF(H6="","Open",IF(I6<=G6,"Met","Breached")) -> Open | K6: T. Alvarez | L6: =DATE(YEAR(B6),MONTH(B6),1) -> 45689
A7: TCK-0006 | B7: 46001.875 | C7: P1 | D7: Data | E7: L2 | F7: Open | G7: 4 | I7: =IF(H7="","",(H7-B7)*24) | J7: =IF(H7="","Open",IF(I7<=G7,"Met","Breached")) -> Open | K7: N. Kowalski | L7: =DATE(YEAR(B7),MONTH(B7),1) -> 45992
A8: TCK-0007 | B8: 45688.988 | C8: P3 | D8: Access | E8: L2 | F8: Open | G8: 24 | I8: =IF(H8="","",(H8-B8)*24) | J8: =IF(H8="","Open",IF(I8<=G8,"Met","Breached")) -> Open | K8: J. Ncube | L8: =DATE(YEAR(B8),MONTH(B8),1) -> 45658
A9: TCK-0008 | B9: 45721.169 | C9: P3 | D9: Change | E9: L2 | F9: Resolved | G9: 24 | H9: 45721.467 | I9: =IF(H9="","",(H9-B9)*24) -> 7.158945 | J9: =IF(H9="","Open",IF(I9<=G9,"Met","Breached")) -> Met | K9: L. Duarte | L9: =DATE(YEAR(B9),MONTH(B9),1) -> 45717
A10: TCK-0009 | B10: 45941.165 | C10: P3 | D10: Hardware | E10: L2 | F10: Resolved | G10: 24 | H10: 45941.466 | I10: =IF(H10="","",(H10-B10)*24) -> 7.2252355 | J10: =IF(H10="","Open",IF(I10<=G10,"Met","Breached")) -> Met | K10: T. Alvarez | L10: =DATE(YEAR(B10),MONTH(B10),1) -> 45931
A11: TCK-0010 | B11: 45746.953 | C11: P3 | D11: Bug | E11: L2 | F11: In Progress | G11: 24 | I11: =IF(H11="","",(H11-B11)*24) | J11: =IF(H11="","Open",IF(I11<=G11,"Met","Breached")) -> Open | K11: A. Mehta | L11: =DATE(YEAR(B11),MONTH(B11),1) -> 45717
A12: TCK-0011 | B12: 45998.347 | C12: P3 | D12: Access | E12: L1 | F12: Resolved | G12: 24 | H12: 45998.862 | I12: =IF(H12="","",(H12-B12)*24) -> 12.342842 | J12: =IF(H12="","Open",IF(I12<=G12,"Met","Breached")) -> Met | K12: N. Kowalski | L12: =DATE(YEAR(B12),MONTH(B12),1) -> 45992
A13: TCK-0012 | B13: 45947.325 | C13: P3 | D13: Bug | E13: L1 | F13: Resolved | G13: 24 | H13: 45947.919 | I13: =IF(H13="","",(H13-B13)*24) -> 14.247959 | J13: =IF(H13="","Open",IF(I13<=G13,"Met","Breached")) -> Met | K13: K. Padilla | L13: =DATE(YEAR(B13),MONTH(B13),1) -> 45931
A14: TCK-0013 | B14: 45855.88 | C14: P3 | D14: Bug | E14: L3 | F14: Closed | G14: 24 | H14: 45856.731 | I14: =IF(H14="","",(H14-B14)*24) -> 20.419817 | J14: =IF(H14="","Open",IF(I14<=G14,"Met","Breached")) -> Met | K14: S. Iyer | L14: =DATE(YEAR(B14),MONTH(B14),1) -> 45839
A15: TCK-0014 | B15: 45807.429 | C15: P2 | D15: Network | E15: L1 | F15: Resolved | G15: 8 | H15: 45807.609 | I15: =IF(H15="","",(H15-B15)*24) -> 4.3366107 | J15: =IF(H15="","Open",IF(I15<=G15,"Met","Breached")) -> Met | K15: R. Fernandes | L15: =DATE(YEAR(B15),MONTH(B15),1) -> 45778
A16: TCK-0015 | B16: 45922.75 | C16: P4 | D16: Access | E16: L2 | F16: In Progress | G16: 72 | I16: =IF(H16="","",(H16-B16)*24) | J16: =IF(H16="","Open",IF(I16<=G16,"Met","Breached")) -> Open | K16: R. Fernandes | L16: =DATE(YEAR(B16),MONTH(B16),1) -> 45901
A17: TCK-0016 | B17: 45719.422 | C17: P4 | D17: Data | E17: L1 | F17: Closed | G17: 72 | H17: 45722.016 | I17: =IF(H17="","",(H17-B17)*24) -> 62.247113 | J17: =IF(H17="","Open",IF(I17<=G17,"Met","Breached")) -> Met | K17: P. Osei | L17: =DATE(YEAR(B17),MONTH(B17),1) -> 45717
A18: TCK-0017 | B18: 45996.076 | C18: P3 | D18: Bug | E18: L1 | F18: Closed | G18: 24 | H18: 45996.598 | I18: =IF(H18="","",(H18-B18)*24) -> 12.531036 | J18: =IF(H18="","Open",IF(I18<=G18,"Met","Breached")) -> Met | K18: R. Fernandes | L18: =DATE(YEAR(B18),MONTH(B18),1) -> 45992
A19: TCK-0018 | B19: 46014.707 | C19: P3 | D19: Bug | E19: L1 | F19: Open | G19: 24 | I19: =IF(H19="","",(H19-B19)*24) | J19: =IF(H19="","Open",IF(I19<=G19,"Met","Breached")) -> Open | K19: T. Alvarez | L19: =DATE(YEAR(B19),MONTH(B19),1) -> 45992
A20: TCK-0019 | B20: 45750.994 | C20: P2 | D20: Data | E20: L3 | F20: Closed | G20: 8 | H20: 45751.304 | I20: =IF(H20="","",(H20-B20)*24) -> 7.4453039 | J20: =IF(H20="","Open",IF(I20<=G20,"Met","Breached")) -> Met | K20: J. Ncube | L20: =DATE(YEAR(B20),MONTH(B20),1) -> 45748
A21: TCK-0020 | B21: 45955.421 | C21: P3 | D21: Access | E21: L3 | F21: Closed | G21: 24 | H21: 45956.351 | I21: =IF(H21="","",(H21-B21)*24) -> 22.333663 | J21: =IF(H21="","Open",IF(I21<=G21,"Met","Breached")) -> Met | K21: T. Alvarez | L21: =DATE(YEAR(B21),MONTH(B21),1) -> 45931
A22: TCK-0021 | B22: 46018.754 | C22: P3 | D22: Hardware | E22: L1 | F22: Resolved | G22: 24 | H22: 46019.094 | I22: =IF(H22="","",(H22-B22)*24) -> 8.1575076 | J22: =IF(H22="","Open",IF(I22<=G22,"Met","Breached")) -> Met | K22: K. Padilla | L22: =DATE(YEAR(B22),MONTH(B22),1) -> 45992
A23: TCK-0022 | B23: 45704.993 | C23: P3 | D23: Change | E23: L3 | F23: Closed | G23: 24 | H23: 45706.08 | I23: =IF(H23="","",(H23-B23)*24) -> 26.083439 | J23: =IF(H23="","Open",IF(I23<=G23,"Met","Breached")) -> Breached | K23: M. Choudhury | L23: =DATE(YEAR(B23),MONTH(B23),1) -> 45689
A24: TCK-0023 | B24: 45746.912 | C24: P3 | D24: Access | E24: L1 | F24: Closed | G24: 24 | H24: 45748.54 | I24: =IF(H24="","",(H24-B24)*24) -> 39.077997 | J24: =IF(H24="","Open",IF(I24<=G24,"Met","Breached")) -> Breached | K24: A. Mehta | L24: =DATE(YEAR(B24),MONTH(B24),1) -> 45717
A25: TCK-0024 | B25: 45938.922 | C25: P2 | D25: Change | E25: L1 | F25: In Progress | G25: 8 | I25: =IF(H25="","",(H25-B25)*24) | J25: =IF(H25="","Open",IF(I25<=G25,"Met","Breached")) -> Open | K25: S. Iyer | L25: =DATE(YEAR(B25),MONTH(B25),1) -> 45931
A26: TCK-0025 | B26: 45694.632 | C26: P2 | D26: Change | E26: L2 | F26: Closed | G26: 8 | H26: 45694.78 | I26: =IF(H26="","",(H26-B26)*24) -> 3.551425 | J26: =IF(H26="","Open",IF(I26<=G26,"Met","Breached")) -> Met | K26: K. Padilla | L26: =DATE(YEAR(B26),MONTH(B26),1) -> 45689
A27: TCK-0026 | B27: 45681.54 | C27: P3 | D27: Network | E27: L2 | F27: Closed | G27: 24 | H27: 45682.391 | I27: =IF(H27="","",(H27-B27)*24) -> 20.432531 | J27: =IF(H27="","Open",IF(I27<=G27,"Met","Breached")) -> Met | K27: R. Fernandes | L27: =DATE(YEAR(B27),MONTH(B27),1) -> 45658
A28: TCK-0027 | B28: 45766.176 | C28: P2 | D28: Change | E28: L1 | F28: Resolved | G28: 8 | H28: 45766.216 | I28: =IF(H28="","",(H28-B28)*24) -> 0.96086357 | J28: =IF(H28="","Open",IF(I28<=G28,"Met","Breached")) -> Met | K28: S. Iyer | L28: =DATE(YEAR(B28),MONTH(B28),1) -> 45748
A29: TCK-0028 | B29: 45982.681 | C29: P4 | D29: Access | E29: L1 | F29: Closed | G29: 72 | H29: 45989.787 | I29: =IF(H29="","",(H29-B29)*24) -> 170.54925 | J29: =IF(H29="","Open",IF(I29<=G29,"Met","Breached")) -> Breached | K29: T. Alvarez | L29: =DATE(YEAR(B29),MONTH(B29),1) -> 45962
A30: TCK-0029 | B30: 46008.474 | C30: P3 | D30: Change | E30: L1 | F30: Closed | G30: 24 | H30: 46009.44 | I30: =IF(H30="","",(H30-B30)*24) -> 23.192093 | J30: =IF(H30="","Open",IF(I30<=G30,"Met","Breached")) -> Met | K30: P. Osei | L30: =DATE(YEAR(B30),MONTH(B30),1) -> 45992
A31: TCK-0030 | B31: 45915.045 | C31: P4 | D31: Change | E31: L1 | F31: Resolved | G31: 72 | H31: 45916.023 | I31: =IF(H31="","",(H31-B31)*24) -> 23.467556 | J31: =IF(H31="","Open",IF(I31<=G31,"Met","Breached")) -> Met | K31: T. Alvarez | L31: =DATE(YEAR(B31),MONTH(B31),1) -> 45901
A32: TCK-0031 | B32: 45680.201 | C32: P3 | D32: Hardware | E32: L1 | F32: Closed | G32: 24 | H32: 45681.106 | I32: =IF(H32="","",(H32-B32)*24) -> 21.720721 | J32: =IF(H32="","Open",IF(I32<=G32,"Met","Breached")) -> Met | K32: L. Duarte | L32: =DATE(YEAR(B32),MONTH(B32),1) -> 45658
A33: TCK-0032 | B33: 45684.611 | C33: P1 | D33: Hardware | E33: L1 | F33: Closed | G33: 4 | H33: 45684.656 | I33: =IF(H33="","",(H33-B33)*24) -> 1.0749585 | J33: =IF(H33="","Open",IF(I33<=G33,"Met","Breached")) -> Met | K33: S. Iyer | L33: =DATE(YEAR(B33),MONTH(B33),1) -> 45658
A34: TCK-0033 | B34: 45898.544 | C34: P4 | D34: Bug | E34: L2 | F34: Closed | G34: 72 | H34: 45900.271 | I34: =IF(H34="","",(H34-B34)*24) -> 41.447595 | J34: =IF(H34="","Open",IF(I34<=G34,"Met","Breached")) -> Met | K34: A. Mehta | L34: =DATE(YEAR(B34),MONTH(B34),1) -> 45870
A35: TCK-0034 | B35: 45761.154 | C35: P2 | D35: Network | E35: L2 | F35: Closed | G35: 8 | H35: 45761.264 | I35: =IF(H35="","",(H35-B35)*24) -> 2.6319783 | J35: =IF(H35="","Open",IF(I35<=G35,"Met","Breached")) -> Met | K35: K. Padilla | L35: =DATE(YEAR(B35),MONTH(B35),1) -> 45748
A36: TCK-0035 | B36: 45876.645 | C36: P4 | D36: Access | E36: L1 | F36: Open | G36: 72 | I36: =IF(H36="","",(H36-B36)*24) | J36: =IF(H36="","Open",IF(I36<=G36,"Met","Breached")) -> Open | K36: N. Kowalski | L36: =DATE(YEAR(B36),MONTH(B36),1) -> 45870
A37: TCK-0036 | B37: 46000.094 | C37: P3 | D37: Hardware | E37: L1 | F37: Closed | G37: 24 | H37: 46000.409 | I37: =IF(H37="","",(H37-B37)*24) -> 7.5609186 | J37: =IF(H37="","Open",IF(I37<=G37,"Met","Breached")) -> Met | K37: L. Duarte | L37: =DATE(YEAR(B37),MONTH(B37),1) -> 45992
A38: TCK-0037 | B38: 45661.038 | C38: P3 | D38: Data | E38: L2 | F38: Closed | G38: 24 | H38: 45661.955 | I38: =IF(H38="","",(H38-B38)*24) -> 21.996795 | J38: =IF(H38="","Open",IF(I38<=G38,"Met","Breached")) -> Met | K38: T. Alvarez | L38: =DATE(YEAR(B38),MONTH(B38),1) -> 45658
A39: TCK-0038 | B39: 45946.326 | C39: P4 | D39: Data | E39: L1 | F39: Resolved | G39: 72 | H39: 45948.164 | I39: =IF(H39="","",(H39-B39)*24) -> 44.099405 | J39: =IF(H39="","Open",IF(I39<=G39,"Met","Breached")) -> Met | K39: R. Fernandes | L39: =DATE(YEAR(B39),MONTH(B39),1) -> 45931
A40: TCK-0039 | B40: 45847.727 | C40: P2 | D40: Network | E40: L2 | F40: Closed | G40: 8 | H40: 45847.759 | I40: =IF(H40="","",(H40-B40)*24) -> 0.77794377 | J40: =IF(H40="","Open",IF(I40<=G40,"Met","Breached")) -> Met | K40: T. Alvarez | L40: =DATE(YEAR(B40),MONTH(B40),1) -> 45839
...

Sheet Dashboard
B2: SLA and Support Ticket Tracker: Dashboard
B4: Total Tickets | D4: SLA Compliance % | F4: Open Tickets | H4: Total Breaches | J4: Avg Resolution Hours
B5: =COUNTA(Tickets!A2:A181) -> 180 | D5: =COUNTIF(Tickets!J2:J181,"Met")/(COUNTIF(Tickets!J2:J181,"Met")+COUNTIF(Tickets!J2:J181,"Breached")) -> 0.81428571 | F5: =COUNTIF(Tickets!J2:J181,"Open") -> 40 | H5: =COUNTIF(Tickets!J2:J181,"Breached") -> 26 | J5: =AVERAGEIF(Tickets!I2:I181,"<>",Tickets!I2:I181) -> 22.899699
B8: Charts above are PivotCharts with Priority + Tier slicers. Supporting PivotTables are below (row 40+).
B44: Supporting PivotTables (source data behind the 4 charts above) | V44: SLA_Status | W44: Breached
B46: Count of Tickets | C46: Column Labels | L46: Row Labels | M46: Count of Tickets | V46: Row Labels | W46: Count of Tickets | AF46: Count of Tickets | AG46: Column Labels
B47: Row Labels | C47: P1 | D47: P2 | E47: P3 | F47: P4 | G47: Grand Total | L47: Breached | M47: 26 | V47: P1 | W47: 1 | AF47: Row Labels | AG47: Closed | AH47: In Progress | AI47: Open | AJ47: Resolved | AK47: Grand Total
B48: L1 | C48: 3 | D48: 17 | E48: 51 | F48: 22 | G48: 93 | L48: Met | M48: 114 | V48: P2 | W48: 8 | AF48: 45658 | AG48: 13 | AH48: 3 | AI48: 1 | AJ48: 3 | AK48: 20
B49: L2 | C49: 5 | D49: 19 | E49: 31 | F49: 14 | G49: 69 | L49: Grand Total | M49: 140 | V49: P3 | W49: 11 | AF49: 45689 | AG49: 7 | AH49: 2 | AI49: 1 | AJ49: 2 | AK49: 12
B50: L3 | C50: 1 | D50: 4 | E50: 12 | F50: 1 | G50: 18 | V50: P4 | W50: 6 | AF50: 45717 | AG50: 8 | AH50: 2 | AI50: 1 | AJ50: 4 | AK50: 15
B51: Grand Total | C51: 9 | D51: 40 | E51: 94 | F51: 37 | G51: 180 | V51: Grand Total | W51: 26 | AF51: 45748 | AG51: 9 | AH51: 1 | AI51: 3 | AJ51: 3 | AK51: 16
AF52: 45778 | AG52: 9 | AH52: 2 | AI52: 2 | AJ52: 3 | AK52: 16
AF53: 45809 | AG53: 7 | AH53: 3 | AI53: 2 | AJ53: 4 | AK53: 16
AF54: 45839 | AG54: 5 | AJ54: 4 | AK54: 9
AF55: 45870 | AG55: 7 | AI55: 2 | AJ55: 3 | AK55: 12
AF56: 45901 | AG56: 7 | AH56: 2 | AI56: 5 | AJ56: 4 | AK56: 18
AF57: 45931 | AG57: 6 | AH57: 1 | AI57: 1 | AJ57: 6 | AK57: 14
AF58: 45962 | AG58: 11 | AH58: 2 | AI58: 1 | AJ58: 3 | AK58: 17
AF59: 45992 | AG59: 8 | AH59: 1 | AI59: 2 | AJ59: 4 | AK59: 15
AF60: Grand Total | AG60: 97 | AH60: 19 | AI60: 21 | AJ60: 43 | AK60: 180
